Workbook

Sheet hr_daily_fact
A1: employee_id | B1: date | C1: in_ts | D1: out_ts | E1: worked_hours | F1: shift_id | G1: standard_hours_per_day | H1: overtime_hours | I1: absent_flag | J1: leave_type | K1: is_paid_leave | L1: true_absent | M1: emp_name | N1: department_name
A2: E001 | B2: 45659 | C2: 45659.376 | D2: 45659.753 | E2: 9.05 | F2: S1 | G2: 8 | H2: 1.05 | I2: FALSE | K2: FALSE | L2: FALSE | M2: =_xlfn.XLOOKUP(A2, hr_employee_dim!A:A, hr_employee_dim!B:B) -> Aarav Sharma | N2: =_xlfn.XLOOKUP(A2, hr_employee_dim!A:A, hr_employee_dim!I:I) -> Analytics
A3: E001 | B3: 45660 | C3: 45660.374 | D3: 45660.751 | E3: 9.0333333 | F3: S1 | G3: 8 | H3: 1.0333333 | I3: FALSE | K3: FALSE | L3: FALSE | M3: =_xlfn.XLOOKUP(A3, hr_employee_dim!A:A, hr_employee_dim!B:B) -> Aarav Sharma | N3: =_xlfn.XLOOKUP(A3, hr_employee_dim!A:A, hr_employee_dim!I:I) -> Analytics
A4: E001 | B4: 45663 | C4: 45663.382 | D4: 45663.755 | E4: 8.95 | F4: S1 | G4: 8 | H4: 0.95 | I4: FALSE | K4: FALSE | L4: FALSE | M4: =_xlfn.XLOOKUP(A4, hr_employee_dim!A:A, hr_employee_dim!B:B) -> Aarav Sharma | N4: =_xlfn.XLOOKUP(A4, hr_employee_dim!A:A, hr_employee_dim!I:I) -> Analytics
A5: E001 | B5: 45664 | C5: 45664.377 | D5: 45664.751 | E5: 8.9833333 | F5: S1 | G5: 8 | H5: 0.98333333 | I5: FALSE | K5: FALSE | L5: FALSE | M5: =_xlfn.XLOOKUP(A5, hr_employee_dim!A:A, hr_employee_dim!B:B) -> Aarav Sharma | N5: =_xlfn.XLOOKUP(A5, hr_employee_dim!A:A, hr_employee_dim!I:I) -> Analytics
A6: E001 | B6: 45665 | C6: 45665.376 | D6: 45665.754 | E6: 9.0833333 | F6: S1 | G6: 8 | H6: 1.0833333 | I6: FALSE | K6: FALSE | L6: FALSE | M6: =_xlfn.XLOOKUP(A6, hr_employee_dim!A:A, hr_employee_dim!B:B) -> Aarav Sharma | N6: =_xlfn.XLOOKUP(A6, hr_employee_dim!A:A, hr_employee_dim!I:I) -> Analytics
A7: E001 | B7: 45691 | C7: 45691.375 | D7: 45691.75 | E7: 9 | F7: S1 | G7: 8 | H7: 1 | I7: FALSE | K7: FALSE | L7: FALSE | M7: =_xlfn.XLOOKUP(A7, hr_employee_dim!A:A, hr_employee_dim!B:B) -> Aarav Sharma | N7: =_xlfn.XLOOKUP(A7, hr_employee_dim!A:A, hr_employee_dim!I:I) -> Analytics
A8: E001 | B8: 45692 | C8: 45692.378 | D8: 45692.752 | E8: 8.9666667 | F8: S1 | G8: 8 | H8: 0.96666667 | I8: FALSE | K8: FALSE | L8: FALSE | M8: =_xlfn.XLOOKUP(A8, hr_employee_dim!A:A, hr_employee_dim!B:B) -> Aarav Sharma | N8: =_xlfn.XLOOKUP(A8, hr_employee_dim!A:A, hr_employee_dim!I:I) -> Analytics
A9: E001 | B9: 45693 | C9: 45693.376 | D9: 45693.753 | E9: 9.05 | F9: S1 | G9: 8 | H9: 1.05 | I9: FALSE | K9: FALSE | L9: FALSE | M9: =_xlfn.XLOOKUP(A9, hr_employee_dim!A:A, hr_employee_dim!B:B) -> Aarav Sharma | N9: =_xlfn.XLOOKUP(A9, hr_employee_dim!A:A, hr_employee_dim!I:I) -> Analytics
A10: E002 | B10: 45659 | C10: 45659.382 | D10: 45659.764 | E10: 9.1666667 | F10: S1 | G10: 8 | H10: 1.1666667 | I10: FALSE | K10: FALSE | L10: FALSE | M10: =_xlfn.XLOOKUP(A10, hr_employee_dim!A:A, hr_employee_dim!B:B) -> Diya Verma | N10: =_xlfn.XLOOKUP(A10, hr_employee_dim!A:A, hr_employee_dim!I:I) -> Analytics
A11: E002 | B11: 45660 | C11: 45660.378 | D11: 45660.76 | E11: 9.1666667 | F11: S1 | G11: 8 | H11: 1.1666667 | I11: FALSE | K11: FALSE | L11: FALSE | M11: =_xlfn.XLOOKUP(A11, hr_employee_dim!A:A, hr_employee_dim!B:B) -> Diya Verma | N11: =_xlfn.XLOOKUP(A11, hr_employee_dim!A:A, hr_employee_dim!I:I) -> Analytics
A12: E002 | B12: 45691 | C12: 45691.383 | D12: 45691.765 | E12: 9.1666667 | F12: S1 | G12: 8 | H12: 1.1666667 | I12: FALSE | K12: FALSE | L12: FALSE | M12: =_xlfn.XLOOKUP(A12, hr_employee_dim!A:A, hr_employee_dim!B:B) -> Diya Verma | N12: =_xlfn.XLOOKUP(A12, hr_employee_dim!A:A, hr_employee_dim!I:I) -> Analytics
A13: E003 | B13: 45659 | C13: 45659.417 | D13: 45659.793 | E13: 9.0166667 | F13: S2 | G13: 8 | H13: 1.0166667 | I13: FALSE | K13: FALSE | L13: FALSE | M13: =_xlfn.XLOOKUP(A13, hr_employee_dim!A:A, hr_employee_dim!B:B) -> Rahul Jain | N13: =_xlfn.XLOOKUP(A13, hr_employee_dim!A:A, hr_employee_dim!I:I) -> Human Resources
... A46: E015 | B46: 45659 | C46: 45659.385 | D46: 45659.76 | E46: 9 | F46: S1 | G46: 8 | H46: 1 | I46: FALSE | K46: FALSE | L46: FALSE | M46: =_xlfn.XLOOKUP(A46, hr_employee_dim!A:A, hr_employee_dim!B:B) -> Manish Kumar | N46: =_xlfn.XLOOKUP(A46, hr_employee_dim!A:A, hr_employee_dim!I:I) -> Engineering
A47: E015 | B47: 45660 | C47: 45660.385 | D47: 45660.76 | E47: 9 | F47: S1 | G47: 8 | H47: 1 | I47: FALSE | J47: Casual | K47: TRUE | L47: FALSE | M47: =_xlfn.XLOOKUP(A47, hr_employee_dim!A:A, hr_employee_dim!B:B) -> Manish Kumar | N47: =_xlfn.XLOOKUP(A47, hr_employee_dim!A:A, hr_employee_dim!I:I) -> Engineering
A48: E015 | B48: 45691 | C48: 45691.385 | D48: 45691.76 | E48: 9 | F48: S1 | G48: 8 | H48: 1 | I48: FALSE | K48: FALSE | L48: FALSE | M48: =_xlfn.XLOOKUP(A48, hr_employee_dim!A:A, hr_employee_dim!B:B) -> Manish Kumar | N48: =_xlfn.XLOOKUP(A48, hr_employee_dim!A:A, hr_employee_dim!I:I) -> Engineering
A49: E016 | B49: 45659 | C49: 45659.386 | D49: 45659.761 | E49: 9 | F49: S3 | G49: 8 | H49: 1 | I49: FALSE | K49: FALSE | L49: FALSE | M49: =_xlfn.XLOOKUP(A49, hr_employee_dim!A:A, hr_employee_dim!B:B) -> Shreya Iyer | N49: =_xlfn.XLOOKUP(A49, hr_employee_dim!A:A, hr_employee_dim!I:I) -> IT Support
A50: E016 | B50: 45660 | C50: 45660.386 | D50: 45660.761 | E50: 9 | F50: S3 | G50: 8 | H50: 1 | I50: FALSE | K50: FALSE | L50: FALSE | M50: =_xlfn.XLOOKUP(A50, hr_employee_dim!A:A, hr_employee_dim!B:B) -> Shreya Iyer | N50: =_xlfn.XLOOKUP(A50, hr_employee_dim!A:A, hr_employee_dim!I:I) -> IT Support
A51: E016 | B51: 45691 | C51: 45691.386 | D51: 45691.761 | E51: 9 | F51: S3 | G51: 8 | H51: 1 | I51: FALSE | K51: FALSE | L51: FALSE | M51: =_xlfn.XLOOKUP(A51, hr_employee_dim!A:A, hr_employee_dim!B:B) -> Shreya Iyer | N51: =_xlfn.XLOOKUP(A51, hr_employee_dim!A:A, hr_employee_dim!I:I) -> IT Support
A52: E017 | B52: 45659 | C52: 45659.387 | D52: 45659.762 | E52: 9 | F52: S2 | G52: 8 | H52: 1 | I52: FALSE | K52: FALSE | L52: FALSE | M52: =_xlfn.XLOOKUP(A52, hr_employee_dim!A:A, hr_employee_dim!B:B) -> Siddharth Roy | N52: =_xlfn.XLOOKUP(A52, hr_employee_dim!A:A, hr_employee_dim!I:I) -> Human Resources
A53: E017 | B53: 45660 | C53: 45660.387 | D53: 45660.762 | E53: 9 | F53: S2 | G53: 8 | H53: 1 | I53: FALSE | K53: FALSE | L53: FALSE | M53: =_xlfn.XLOOKUP(A53, hr_employee_dim!A:A, hr_employee_dim!B:B) -> Siddharth Roy | N53: =_xlfn.XLOOKUP(A53, hr_employee_dim!A:A, hr_employee_dim!I:I) -> Human Resources
A54: E017 | B54: 45691 | C54: 45691.387 | D54: 45691.762 | E54: 9 | F54: S2 | G54: 8 | H54: 1 | I54: FALSE | K54: FALSE | L54: FALSE | M54: =_xlfn.XLOOKUP(A54, hr_employee_dim!A:A, hr_employee_dim!B:B) -> Siddharth Roy | N54: =_xlfn.XLOOKUP(A54, hr_employee_dim!A:A, hr_employee_dim!I:I) -> Human Resources
A55: E018 | B55: 45659 | C55: 45659.387 | D55: 45659.762 | E55: 9 | F55: S1 | G55: 8 | H55: 1 | I55: FALSE | K55: FALSE | L55: FALSE | M55: =_xlfn.XLOOKUP(A55, hr_employee_dim!A:A, hr_employee_dim!B:B) -> Tanvi Bose | N55: =_xlfn.XLOOKUP(A55, hr_employee_dim!A:A, hr_employee_dim!I:I) -> Analytics
A56: E018 | B56: 45660 | C56: 45660.387 | D56: 45660.762 | E56: 9 | F56: S1 | G56: 8 | H56: 1 | I56: FALSE | K56: FALSE | L56: FALSE | M56: =_xlfn.XLOOKUP(A56, hr_employee_dim!A:A, hr_employee_dim!B:B) -> Tanvi Bose | N56: =_xlfn.XLOOKUP(A56, hr_employee_dim!A:A, hr_employee_dim!I:I) -> Analytics
A57: E018 | B57: 45691 | C57: 45691.387 | D57: 45691.762 | E57: 9 | F57: S1 | G57: 8 | H57: 1 | I57: FALSE | K57: FALSE | L57: FALSE | M57: =_xlfn.XLOOKUP(A57, hr_employee_dim!A:A, hr_employee_dim!B:B) -> Tanvi Bose | N57: =_xlfn.XLOOKUP(A57, hr_employee_dim!A:A, hr_employee_dim!I:I) -> Analytics
A58: E019 | B58: 45659 | C58: 45659.388 | D58: 45659.763 | E58: 9 | F58: S1 | G58: 8 | H58: 1 | I58: FALSE | K58: FALSE | L58: FALSE | M58: =_xlfn.XLOOKUP(A58, hr_employee_dim!A:A, hr_employee_dim!B:B) -> Harsh Vardhan | N58: =_xlfn.XLOOKUP(A58, hr_employee_dim!A:A, hr_employee_dim!I:I) -> Engineering
A59: E019 | B59: 45660 | C59: 45660.388 | D59: 45660.763 | E59: 9 | F59: S1 | G59: 8 | H59: 1 | I59: FALSE | K59: FALSE | L59: FALSE | M59: =_xlfn.XLOOKUP(A59, hr_employee_dim!A:A, hr_employee_dim!B:B) -> Harsh Vardhan | N59: =_xlfn.XLOOKUP(A59, hr_employee_dim!A:A, hr_employee_dim!I:I) -> Engineering
... A93: E030 | B93: 45691 | C93: 45691.396 | D93: 45691.771 | E93: 9 | F93: S2 | G93: 8 | H93: 1 | I93: FALSE | K93: FALSE | L93: FALSE | M93: =_xlfn.XLOOKUP(A93, hr_employee_dim!A:A, hr_employee_dim!B:B) -> Karishma Paul | N93: =_xlfn.XLOOKUP(A93, hr_employee_dim!A:A, hr_employee_dim!I:I) -> Finance

Sheet hr_employee_dim
A1: employee_id | B1: emp_name | C1: hire_date | D1: termination_date | E1: department_id | F1: job_role | G1: payroll_grade | H1: shift_id | I1: department_name | J1: manager_id
A2: E001 | B2: Aarav Sharma | C2: 44967 | E2: D01 | F2: Data Analyst | G2: G4 | H2: S1 | I2: Analytics | J2: E027
A3: E002 | B3: Diya Verma | C3: 44870 | E3: D01 | F3: Senior Data Analyst | G3: G5 | H3: S1 | I3: Analytics | J3: E027
A4: E003 | B4: Rahul Jain | C4: 45306 | E4: D02 | F4: HR Executive | G4: G3 | H4: S2 | I4: Human Resources | J4: E010
A5: E004 | B5: Ananya Singh | C5: 44397 | E5: D03 | F5: Software Engineer | G5: G4 | H5: S1 | I5: Engineering | J5: E015
A6: E005 | B6: Vikram Rao | C6: 44105 | E6: D03 | F6: Senior Developer | G6: G6 | H6: S1 | I6: Engineering | J6: E015
A7: E006 | B7: Neha Gupta | C7: 45095 | E7: D04 | F7: Accountant | G7: G4 | H7: S2 | I7: Finance | J7: E007
A8: E007 | B8: Arjun Mehta | C8: 44642 | E8: D04 | F8: Finance Manager | G8: G6 | H8: S2 | I8: Finance | J8: E007
A9: E008 | B9: Isha Nair | C9: 45421 | E9: D05 | F9: Support Engineer | G9: G3 | H9: S3 | I9: IT Support | J9: E009
A10: E009 | B10: Kunal Patel | C10: 45180 | E10: D05 | F10: Support Lead | G10: G4 | H10: S3 | I10: IT Support | J10: E009
A11: E010 | B11: Pooja Desai | C11: 44896 | E11: D02 | F11: HR Manager | G11: G5 | H11: S2 | I11: Human Resources | J11: E010
A12: E011 | B12: Rohan Das | C12: 44201 | E12: D01 | F12: BI Developer | G12: G4 | H12: S1 | I12: Analytics | J12: E027
A13: E012 | B13: Sneha Kulkarni | C13: 45030 | E13: D03 | F13: QA Engineer | G13: G3 | H13: S1 | I13: Engineering | J13: E015
... A31: E030 | B31: Karishma Paul | C31: 44613 | E31: D04 | F31: Business Analyst | G31: G4 | H31: S2 | I31: Finance | J31: E007

Sheet Monthly Worked Hours
A3: Row Labels | B3: Sum of worked_hours
A4: E001
A5: Aarav Sharma | B5: 72.116667
A6: E002
A7: Diya Verma | B7: 27.5
A8: E003
A9: Rahul Jain | B9: 17.933333
A10: E004
A11: Ananya Singh | B11: 18.283333
A12: E005
A13: Vikram Rao | B13: 18.316667
A14: E006
A15: Neha Gupta | B15: 27
A16: E007
A17: Arjun Mehta | B17: 27
A18: E008
A19: Isha Nair | B19: 27
A20: E009
A21: Kunal Patel | B21: 27
A22: E010
A23: Pooja Desai | B23: 27
A24: E011
A25: Rohan Das | B25: 27
A26: E012
A27: Sneha Kulkarni | B27: 27
A28: E013
A29: Aditya Mishra | B29: 27
A30: E014
A31: Kritika Yadav | B31: 27
A32: E015
A33: Manish Kumar | B33: 27
A34: E016
A35: Shreya Iyer | B35: 27
A36: E017
A37: Siddharth Roy | B37: 27
A38: E018
A39: Tanvi Bose | B39: 27
A40: E019
A41: Harsh Vardhan | B41: 27
A42: E020
...

Sheet Overtime Summary
A3: Row Labels | B3: Sum of overtime_hours
A4: Analytics | B4: 26.616667
A5: Engineering | B5: 19.6
A6: Finance | B6: 18
A7: Human Resources | B7: 13.933333
A8: IT Support | B8: 15
A9: Grand Total | B9: 93.15

Sheet Department Strength
A3: Row Labels | B3: Count of employee_id
A4: Analytics | B4: 26
A5: Engineering | B5: 19
A6: Finance | B6: 18
A7: Human Resources | B7: 14
A8: IT Support | B8: 15
A9: Grand Total | B9: 92
